Workbook
Name OO: #REF!
Name ProbThreshold: #REF!
Name Rules: #REF!

Sheet TB & MCC Cost Audit 2020-Curren
A1: Open
L2: Budget | P2: Actual
L3: Revenue | M3: COGS | N3: Gross Profit | P3: Revenue | Q3: COGS | W3: COGS | Z3: Gross Profit
A4: Project | B4: Opportunity | C4: Type | D4: Year | E4: Month | F4: Invoice # | G4: Item Number | H4: GL Account | I4: Size | J4: Size Description | K4: Item Description | L4: Budget Revenue | M4: Budget Cost | N4: Budget GP $ | O4: Budget GP% | P4: Actual Revenue | Q4: WO # | R4: Labor Hrs | S4: Labor/OH $ | T4: Exp Rpts | U4: Material | V4: Shipping | W4: Total Actual Cost | X4: Actual Lab/OH Rate | Y4: Actual Material % | Z4: Actual GP $ | AA4: Actual GP % | AB4: B vs A $ | AC4: Variance | AD4: Comments
A5: Dekalb | C5: TBEN | D5: 2020 | E5: 43889 | F5: 160107 | G5: 400240TB | I5: 1 | J5: TB Small | K5: 2400 STD TB | L5: =285779-1 -> 285778 | M5: =L5*(1-O5) -> 128600.1 | N5: =L5-M5 -> 157177.9 | O5: =1-0.45 -> 0.55 | P5: 100126.28 | Q5: 554 | R5: =29.5+19.5 -> 49 | S5: =1203.26+509.4 -> 1712.66 | T5: 0 | U5: 22484.52 | W5: =SUM(S5:V5) -> 24197.18 | X5: =IFERROR(S5/R5,"") -> 34.952245 | Y5: =U5/P5 -> 0.22456162 | Z5: =P5-W5 -> 75929.1 | AA5: =Z5/P5 -> 0.75833338
A6: Dekalb | C6: TBEN | D6: 2020 | E6: 43889 | F6: 160107 | G6: 400247TB | I6: 1 | J6: TB Small | K6: 2410 ADV TB | L6: 0 | M6: =L6*(1-O6) -> 0 | N6: =L6-M6 -> 0 | O6: =1-0.45 -> 0.55 | P6: 126153.56 | Q6: 731 | R6: =24.5+23 -> 47.5 | S6: =1215.4+547.03 -> 1762.43 | T6: 0 | U6: 29128.1 | W6: =SUM(S6:V6) -> 30890.53 | X6: =IFERROR(S6/R6,"") -> 37.103789 | Y6: =U6/P6 -> 0.230894 | Z6: =P6-W6 -> 95263.03 | AA6: =Z6/P6 -> 0.75513549
A7: Dekalb | C7: TBEN | D7: 2020 | E7: 43889 | F7: 160107 | G7: 220100119 | K7: Tank Duplex 100 Gal | L7: 0 | M7: =L7*(1-O7) -> 0 | N7: =L7-M7 -> 0 | O7: =1-0.45 -> 0.55 | P7: 9800 | Q7: 881 | R7: 0 | S7: 0 | T7: 0 | U7: 10992.08 | W7: =SUM(S7:V7) -> 10992.08 | X7: =IFERROR(S7/R7,"") | Y7: =U7/P7 -> 1.1216408 | Z7: =P7-W7 -> -1192.08 | AA7: =Z7/P7 -> -0.12164082
A8: Dekalb | C8: TBEN | D8: 2020 | E8: 43889 | F8: 160107 | G8: TBRECIRC | K8: Test Bench Recir System | L8: 0 | M8: =L8*(1-O8) -> 0 | N8: =L8-M8 -> 0 | O8: =1-0.45 -> 0.55 | P8: 63250.96 | Q8: 556 | R8: =6.5+25+12.5 -> 44 | S8: =1018.16+416.14 -> 1434.3 | T8: 0 | U8: 17372.69 | W8: =SUM(S8:V8) -> 18806.99 | X8: =IFERROR(S8/R8,"") -> 32.597727 | Y8: =U8/P8 -> 0.27466287 | Z8: =P8-W8 -> 44443.97 | AA8: =Z8/P8 -> 0.7026608
A9: Dekalb | C9: TBEN | D9: 2020 | E9: 43889 | F9: 160107 | G9: 210500119 | K9: Tank - Single - 500 Gallon - A | L9: 0 | M9: =L9*(1-O9) -> 0 | N9: =L9-M9 -> 0 | O9: =1-0.45 -> 0.55 | P9: 19018 | Q9: 882 | R9: 0 | S9: 0 | T9: 0 | U9: 5056.01 | W9: =SUM(S9:V9) -> 5056.01 | X9: =IFERROR(S9/R9,"") | Y9: =U9/P9 -> 0.26585393 | Z9: =P9-W9 -> 13961.99 | AA9: =Z9/P9 -> 0.73414607 | AB9: =M9-W9 -> -5056.01 | AC9: =AA9-O9 -> 0.18414607
A10: Dekalb | C10: TBIN | D10: 2020 | E10: 43889 | F10: 160107 | G10: 516121129 | K10: Test Bench Installation & Trai | L10: 29525 | M10: =L10*(1-O10) -> 14762.5 | N10: =L10-M10 -> 14762.5 | O10: =1-0.5 -> 0.5 | P10: 29525 | Q10: 884 | R10: 165 | S10: =5100.15+2295.15 -> 7395.3 | T10: 5097.02 | U10: 3533.88 | W10: =SUM(S10:V10) -> 16026.2 | X10: =IFERROR(S10/R10,"") -> 44.82 | Y10: =U10/P10 -> 0.11969111 | Z10: =P10-W10 -> 13498.8 | AA10: =Z10/P10 -> 0.45719898 | AB10: =M10-W10 -> -1263.7 | AC10: =AA10-O10 -> -0.042801016
A11: Dekalb | C11: M3IN | D11: 2020 | E11: 43889 | F11: 160107 | G11: /711420120 | K11: M3 Enterprise Software (Annual | L11: 52528 | M11: =L11*(1-O11) -> 1050.56 | N11: =L11-M11 -> 51477.44 | O11: =1-0.02 -> 0.98 | P11: 19958 | W11: =SUM(S11:V11) -> 0 | X11: =IFERROR(S11/R11,"") | Y11: =U11/P11 -> 0 | Z11: =P11-W11 -> 19958 | AA11: =Z11/P11 -> 1 | AB11: =M11-W11 -> 1050.56 | AC11: =AA11-O11 -> 0.02
A12: Dekalb | C12: M3IN | D12: 2020 | E12: 43889 | F12: 160107 | G12: 616420129 | K12: M3 Enterprise Software Install | L12: 10000 | M12: =L12*(1-O12) -> 5290 | N12: =L12-M12 -> 4710 | O12: =1-0.529 -> 0.471 | P12: 10000 | Q12: 885 | R12: 33.5 | S12: =1035.49+465.99 -> 1501.48 | T12: 2058.91 | U12: 3320.38 | W12: =SUM(S12:V12) -> 6880.77 | X12: =IFERROR(S12/R12,"") -> 44.820299 | Y12: =U12/P12 -> 0.332038 | Z12: =P12-W12 -> 3119.23 | AA12: =Z12/P12 -> 0.311923 | AB12: =M12-W12 -> -1590.77 | AC12: =AA12-O12 -> -0.159077
D13: 2020 | E13: 43889 | X13: =IFERROR(S13/R13,"")
A14: Dekalb | C14: Rev Total | D14: 2020 | E14: 43889 | L14: =SUM(L5:L13) -> 377831 | M14: =SUM(M5:M13) -> 149703.16 | N14: =SUM(N5:N13) -> 228127.84 | O14: =((P5*O5)+(P6*O6)+(P7*O7)+(P8*O8)+(P9*O9)+(P10*O10))/P14 -> 0.50248375 | P14: =SUM(P5:P13) -> 377831.8 | R14: =SUM(R5:R13) -> 339 | S14: =SUM(S5:S13) -> 13806.17 | T14: =SUM(T5:T13) -> 7155.93 | U14: =SUM(U5:U13) -> 91887.66 | W14: =SUM(W5:W12) -> 112849.76 | X14: =IFERROR(S14/R14,"") -> 40.726165 | Y14: =U14/P14 -> 0.24319726 | Z14: =P14-W14 -> 264982.04 | AA14: =Z14/P14 -> 0.70132276 | AB14: =M14-W14 -> 36853.4 | AC14: =AA14-O14 -> 0.19883901
A15: Dekalb | C15: SCH | D15: 2020 | E15: 43889 | F15: 160107 | G15: 997080WH | K15: Shipping/Crating/Handling | L15: 0 | M15: 0 | N15: 0 | O15: 0 | P15: 5500 | Q15: 883 | R15: 30.5 | S15: =838.75+377.59 -> 1216.34 | T15: 2289 | U15: 400 | W15: 3905.34 | X15: =IFERROR(S15/R15,"") -> 39.88 | Y15: =U15/P15 -> 0.072727273 | Z15: =P15-W15 -> 1594.66 | AA15: =Z15/P15 -> 0.28993818 | AB15: =M15-W15 -> -3905.34 | AC15: =AA15-O15 -> 0.28993818
A16: Dekalb | C16: DRM3 | D16: 2020 | E16: 43889 | F16: 160107 | G16: /M3RC | K16: M3 Software License Renewal- C | P16: =21821+24003+26404+29044 -> 101272 | X16: =IFERROR(S16/R16,"") | AB16: =M16-W16 -> 0 | AC16: =AA16-O16 -> 0
A17: Dekalb | C17: DRMCC | D17: 2020 | E17: 43889 | F17: 160107 | G17: /811000010 | I17: =MID(G17,3,1) -> 1 | J17: Small/Medium | K17: MCC Annual 2020 | L17: =P17 -> 9680 | M17: =L17*0.3 -> 2904 | N17: =L17-M17 -> 6776 | O17: =N17/L17 -> 0.7 | P17: 9680 | W17: =SUM(S17:V17) -> 0 | X17: =IFERROR(S17/R17,"") | Z17: =P17-W17 -> 9680 | AA17: =Z17/P17 -> 1 | AB17: =M17-W17 -> 2904 | AC17: =AA17-O17 -> 0.3
D18: 2020 | E18: 43889
A19: Dekalb | C19: Inv Total | D19: 2020 | E19: 43889 | P19: =SUM(P14:P17) -> 494283.8 | R19: =SUM(R14:R17) -> 369.5 | S19: =SUM(S14:S17) -> 15022.51 | T19: =SUM(T14:T17) -> 9444.93 | U19: =SUM(U14:U17) -> 92287.66 | W19: =SUM(S19:U19) -> 116755.1 | X19: =IFERROR(S19/R19,"") -> 40.656319 | AB19: =M19-W19 -> -116755.1 | AC19: =AA19-O19 -> 0
A20: Dekalb | C20: Total TBEN | D20: 2020 | E20: 43889 | L20: =L5+L6+L7+L8+L9 -> 285778 | M20: =M5+M6+M7+M8+M9 -> 128600.1 | N20: =N5+N6+N7+N8+N9 -> 157177.9 | O20: =((P5*O5)+(P6*O6)+(P7*O7)+(P8*O8)+(P9*O9))/P20 -> 0.55 | P20: =P5+P6+P7+P8+P9 -> 318348.8 | R20: =R5+R6+R7+R8+R9 -> 140.5 | S20: =S5+S6+S7+S8+S9 -> 4909.39 | T20: =T5+T6+T7+T8+T9 -> 0 | U20: =U5+U6+U7+U8+U9 -> 85033.4 | W20: =W5+W6+W7+W8+W9 -> 89942.79 | X20: =IFERROR(S20/R20,"") -> 34.942278 | Y20: =U20/P20 -> 0.26710765 | Z20: =P20-W20 -> 228406.01 | AA20: =Z20/P20 -> 0.71747093 | AB20: =M20-W20 -> 38657.31 | AC20: =AA20-O20 -> 0.16747093
A22: Coos Bay | C22: TBEN | D22: 2020 | E22: 43889 | F22: 160104 | G22: 123051220 | I22: =MID(G22,2,1) -> 2 | J22: TB Medium | K22: TB New Medium Series 3-510 Mun200 | O22: =1-0.45 -> 0.55 | P22: 44635 | Q22: 831 | R22: =13+14 -> 27 | S22: =688.08+309.7 -> 997.78 | U22: 12206.78 | W22: =SUM(S22:V22) -> 13204.56 | X22: =IFERROR(S22/R22,"") -> 36.954815 | Y22: =U22/P22 -> 0.27348 | Z22: =P22-W22 -> 31430.44 | AA22: =Z22/P22 -> 0.70416579 | AB22: =M22-W22 -> -13204.56 | AC22: =AA22-O22 -> 0.15416579
A23: Coos Bay | C23: TBEN | D23: 2020 | E23: 43889 | F23: 160104 | G23: 220100210 | K23: Tank Duplex 100 Gal | O23: =1-0.45 -> 0.55 | P23: 6600 | Q23: 832 | R23: 2 | S23: =54.08+24.34 -> 78.42 | U23: 4539.48 | W23: =SUM(S23:V23) -> 4617.9 | X23: =IFERROR(S23/R23,"") -> 39.21 | Y23: =U23/P23 -> 0.6878 | Z23: =P23-W23 -> 1982.1 | AA23: =Z23/P23 -> 0.30031818 | AB23: =M23-W23 -> -4617.9 | AC23: =AA23-O23 -> -0.24968182
A24: Coos Bay | C24: TBIN | D24: 2020 | E24: 43889 | F24: 160104 | G24: 523051120 | K24: TB Install & Training | O24: =1-0.45 -> 0.55 | P24: 15965 | Q24: 833 | R24: 41 | S24: =1267.31+570.31 -> 1837.62 | T24: 2158.97 | W24: =SUM(S24:V24) -> 3996.59 | X24: =IFERROR(S24/R24,"") -> 44.82 | Y24: =U24/P24 -> 0 | Z24: =P24-W24 -> 11968.41 | AA24: =Z24/P24 -> 0.74966552 | AB24: =M24-W24 -> -3996.59 | AC24: =AA24-O24 -> 0.19966552
D25: 2020 | E25: 43889 | X25: =IFERROR(S25/R25,"")
A26: Coos Bay | C26: Rev Total | D26: 2020 | E26: 43889 | F26: 160104 | O26: =((P22*O22)+(P23*O23)+(P24*O24))/P26 -> 0.55 | P26: =SUM(P22:P25) -> 67200 | R26: =SUM(R22:R25) -> 70 | S26: =SUM(S22:S25) -> 2913.82 | T26: =SUM(T22:T25) -> 2158.97 | U26: =SUM(U22:U25) -> 16746.26 | W26: =SUM(W22:W25) -> 21819.05 | X26: =IFERROR(S26/R26,"") -> 41.626 | Y26: =U26/P26 -> 0.2492003 | Z26: =P26-W26 -> 45380.95 | AA26: =Z26/P26 -> 0.67531176 | AB26: =M26-W26 -> -21819.05 | AC26: =AA26-O26 -> 0.12531176
A27: Coos Bay | C27: SCH | D27: 2020 | E27: 43889 | F27: 160104 | G27: 997080WH | K27: Shipping / Crating / Handling | O27: 0 | P27: 6500 | Q27: 834 | R27: 8 | S27: =220+99.04 -> 319.04 | T27: 1448.35 | U27: 269.65 | W27: 2037.04 | X27: =IFERROR(S27/R27,"") -> 39.88 | Y27: =U27/P27 -> 0.041484615 | Z27: =P27-W27 -> 4462.96 | AA27: =Z27/P27 -> 0.68660923 | AB27: =M27-W27 -> -2037.04 | AC27: =AA27-O27 -> 0.68660923
D28: 2020 | E28: 43889 | X28: =IFERROR(S28/R28,"")
A29: Coos Bay | C29: Inv Total | D29: 2020 | E29: 43889 | P29: =SUM(P26:P27) -> 73700 | R29: =SUM(R26:R27) -> 78 | S29: =SUM(S26:S27) -> 3232.86 | T29: =SUM(T26:T27) -> 3607.32 | U29: =SUM(U26:U27) -> 17015.91 | W29: =SUM(S29:U29) -> 23856.09 | X29: =IFERROR(S29/R29,"") -> 41.446923 | AB29: =M29-W29 -> -23856.09 | AC29: =AA29-O29 -> 0
A30: Coos Bay | C30: Total TBEN | D30: 2020 | E30: 43889 | O30: =((P22*O22)+(P23*O23)+(P24*O24))/P30 -> 0.55 | P30: =P22+P23+P24 -> 67200 | R30: =R22+R23+R24 -> 70 | S30: =S22+S23+S24 -> 2913.82 | T30: =T22+T23+T24 -> 2158.97 | U30: =U22+U23+U24 -> 16746.26 | W30: =W22+W23+W24 -> 21819.05 | X30: =IFERROR(S30/R30,"") -> 41.626 | Y30: =U30/P30 -> 0.2492003 | Z30: =P30-W30 -> 45380.95 | AA30: =Z30/P30 -> 0.67531176 | AB30: =M30-W30 -> -21819.05 | AC30: =AA30-O30 -> 0.12531176
A32: White House | C32: TBEN | D32: 2020 | E32: 43982 | F32: 160594 | G32: 125100120 | I32: =MID(G32,2,1) -> 2 | J32: TB Medium | K32: TB New Med Series 5 | O32: =1-0.45 -> 0.55 | P32: 110058.37 | Q32: 886 | R32: =14+52 -> 66 | S32: =1766.09+794.88 -> 2560.97 | U32: 27639.17 | W32: =SUM(S32:V32) -> 30200.14 | X32: =IFERROR(S32/R32,"") -> 38.802576 | Y32: =U32/P32 -> 0.25113192 | Z32: =P32-W32 -> 79858.23 | AA32: =Z32/P32 -> 0.72559888 | AB32: =M32-W32 -> -30200.14 | AC32: =AA32-O32 -> 0.17559888
A33: White House | C33: TBEN | D33: 2020 | E33: 43982 | F33: 160594 | G33: 220100110 | K33: Tank New Duplex 100 Gal | O33: =1-0.45 -> 0.55 | P33: 6600 | Q33: 887 | U33: 7885.36 | W33: =SUM(S33:V33) -> 7885.36 | X33: =IFERROR(S33/R33,"") | Y33: =U33/P33 -> 1.1947515 | Z33: =P33-W33 -> -1285.36 | AA33: =Z33/P33 -> -0.19475152 | AB33: =M33-W33 -> -7885.36 | AC33: =AA33-O33 -> -0.74475152
A34: White House | C34: TBEN | D34: 2020 | E34: 43982 | F34: 160594 | G34: 210500110 | K34: Tank New Single 500 Gal | O34: =1-0.45 -> 0.55 | P34: 15000 | Q34: 888 | U34: 5028.47 | W34: =SUM(S34:V34) -> 5028.47 | X34: =IFERROR(S34/R34,"") | Y34: =U34/P34 -> 0.33523133 | Z34: =P34-W34 -> 9971.53 | AA34: =Z34/P34 -> 0.66476867 | AB34: =M34-W34 -> -5028.47 | AC34: =AA34-O34 -> 0.11476867
A35: White House | C35: TBEN | D35: 2020 | E35: 43982 | F35: 160594 | G35: 210010110 | K35: Tank New Single 10 Gal | O35: =1-0.45 -> 0.55 | P35: 8760 | Q35: 889 | R35: 1 | S35: =27.04+12.17 -> 39.21 | U35: 1361.01 | W35: =SUM(S35:V35) -> 1400.22 | X35: =IFERROR(S35/R35,"") -> 39.21 | Y35: =U35/P35 -> 0.15536644 | Z35: =P35-W35 -> 7359.78 | AA35: =Z35/P35 -> 0.84015753 | AB35: =M35-W35 -> -1400.22 | AC35: =AA35-O35 -> 0.29015753
A36: White House | C36: TBIN | D36: 2020 | E36: 43982 | F36: 160594 | G36: 525100120 | K36: TB Install & Training | O36: =1-0.45 -> 0.55 | P36: 14920 | Q36: 890 | R36: 100.75 | S36: =3114.21+1401.46 -> 4515.67 | T36: 6342.27 | U36: 1608.3 | W36: =SUM(S36:V36) -> 12466.24 | X36: =IFERROR(S36/R36,"") -> 44.820546 | Y36: =U36/P36 -> 0.10779491 | Z36: =P36-W36 -> 2453.76 | AA36: =Z36/P36 -> 0.16446113 | AB36: =M36-W36 -> -12466.24 | AC36: =AA36-O36 -> -0.38553887
A37: White House | C37: M3IN | D37: 2020 | E37: 43982 | F37: 160594 | G37: 626520120 | K37: M3 Software install & Train | O37: =1-0.529 -> 0.471 | P37: 6655 | Q37: 891 | R37: 16 | S37: =628.48+282.88 -> 911.36 | T37: 1351.34 | U37: 2322.74 | W37: =SUM(S37:V37) -> 4585.44 | X37: =IFERROR(S37/R37,"") -> 56.96 | Y37: =U37/P37 -> 0.34902179 | Z37: =P37-W37 -> 2069.56 | AA37: =Z37/P37 -> 0.31097821 | AB37: =M37-W37 -> -4585.44 | AC37: =AA37-O37 -> -0.16002179
D38: 2020 | E38: 43982 | X38: =IFERROR(S38/R38,"")
A39: White House | C39: Rev Total | D39: 2020 | E39: 43982 | O39: =((P32*O32)+(P33*O33)+(P34*O34)+(P35*O35))/P39 -> 0.47674855 | P39: =SUM(P32:P37) -> 161993.37 | R39: =SUM(R32:R37) -> 183.75 | S39: =SUM(S32:S37) -> 8027.21 | T39: =SUM(T32:T37) -> 7693.61 | U39: =SUM(U32:U37) -> 45845.05 | W39: =SUM(W32:W38) -> 61565.87 | X39: =IFERROR(S39/R39,"") -> 43.685497 | Y39: =U39/P39 -> 0.28300572 | Z39: =P39-W39 -> 100427.5 | AA39: =Z39/P39 -> 0.61994821 | AB39: =M39-W39 -> -61565.87 | AC39: =AA39-O39 -> 0.14319967
A40: White House | C40: SCH | D40: 2020 | E40: 43982 | F40: 160594 | G40: 997080WH | K40: Shipping / Crating / Handling | O40: 0 | P40: 5210 | Q40: 892 | R40: 18 | S40: =495+222.84 -> 717.84 | T40: 2509.92 | U40: 645.13 | W40: =SUM(S40:V40) -> 3872.89 | X40: =IFERROR(S40/R40,"") -> 39.88 | Y40: =U40/P40 -> 0.12382534 | Z40: =P40-W40 -> 1337.11 | AA40: =Z40/P40 -> 0.25664299 | AB40: =M40-W40 -> -3872.89 | AC40: =AA40-O40 -> 0.25664299
A41: White House | C41: DRM3 | D41: 2020 | E41: 43982 | F41: 160594 | G41: /721520120 | P41: 9979 | X41: =IFERROR(S41/R41,"") | AB41: =M41-W41 -> 0 | AC41: =AA41-O41 -> 0
D42: 2020 | E42: 43982 | X42: =IFERROR(S42/R42,"")
...

Sheet MCC Margin Analysis
A1: MCC
C2: =SUM(C4:C96) -> 936076.39 | D2: =SUM(D4:D96) -> 846560.68 | E2: =SUM(E4:E96) -> 1190947 | F2: =SUM(F4:F96) -> 1441605.4 | G2: =SUM(G4:G96) -> 1336147.9 | J2: =SUM(J4:J96) -> 207210.08 | K2: =SUM(K4:K96) -> 187490.49 | L2: =SUM(L4:L96) -> 236679.49 | M2: =SUM(M4:M96) -> 321230.19 | N2: =SUM(N4:N96) -> 293678.83 | Q2: =IFERROR((C2-J2)/C2," - ") -> 0.77863978 | R2: =IFERROR((D2-K2)/D2," - ") -> 0.77852681 | S2: =IFERROR((E2-L2)/E2," - ") -> 0.80126782 | T2: =IFERROR((F2-M2)/F2," - ") -> 0.77717189 | U2: =IFERROR((G2-N2)/G2," - ") -> 0.78020485
A3: REV | B3: Customer | C3: 2021 | D3: =C3+1 -> 2022 | E3: =D3+1 -> 2023 | F3: =E3+1 -> 2024 | G3: =F3+1 -> 2025 | I3: COGS | J3: 2021 | K3: =J3+1 -> 2022 | L3: =K3+1 -> 2023 | M3: =L3+1 -> 2024 | N3: =M3+1 -> 2025 | P3: GPM % | Q3: 2021 | R3: =Q3+1 -> 2022 | S3: =R3+1 -> 2023 | T3: =S3+1 -> 2024 | U3: =T3+1 -> 2025
B4: Alameda | C4: =SUMIFS('TB & MCC Cost Audit 2020-Curren'!$P:$P,'TB & MCC Cost Audit 2020-Curren'!$C:$C,'MCC Margin Analysis'!$A$1,'TB & MCC Cost Audit 2020-Curren'!$D:$D,'MCC Margin Analysis'!C$3,'TB & MCC Cost Audit 2020-Curren'!$A:$A,'MCC Margin Analysis'!$B4) -> 40676 | D4: =SUMIFS('TB & MCC Cost Audit 2020-Curren'!$P:$P,'TB & MCC Cost Audit 2020-Curren'!$C:$C,'MCC Margin Analysis'!$A$1,'TB & MCC Cost Audit 2020-Curren'!$D:$D,'MCC Margin Analysis'!D$3,'TB & MCC Cost Audit 2020-Curren'!$A:$A,'MCC Margin Analysis'!$B4) -> 31320 | E4: =SUMIFS('TB & MCC Cost Audit 2020-Curren'!$P:$P,'TB & MCC Cost Audit 2020-Curren'!$C:$C,'MCC Margin Analysis'!$A$1,'TB & MCC Cost Audit 2020-Curren'!$D:$D,'MCC Margin Analysis'!E$3,'TB & MCC Cost Audit 2020-Curren'!$A:$A,'MCC Margin Analysis'!$B4) -> 31946 | F4: =SUMIFS('TB & MCC Cost Audit 2020-Curren'!$P:$P,'TB & MCC Cost Audit 2020-Curren'!$C:$C,'MCC Margin Analysis'!$A$1,'TB & MCC Cost Audit 2020-Curren'!$D:$D,'MCC Margin Analysis'!F$3,'TB & MCC Cost Audit 2020-Curren'!$A:$A,'MCC Margin Analysis'!$B4) -> 32584 | G4: =SUMIFS('TB & MCC Cost Audit 2020-Curren'!$P:$P,'TB & MCC Cost Audit 2020-Curren'!$C:$C,'MCC Margin Analysis'!$A$1,'TB & MCC Cost Audit 2020-Curren'!$D:$D,'MCC Margin Analysis'!G$3,'TB & MCC Cost Audit 2020-Curren'!$A:$A,'MCC Margin Analysis'!$B4) -> 33236 | J4: =SUMIFS('TB & MCC Cost Audit 2020-Curren'!$W:$W,'TB & MCC Cost Audit 2020-Curren'!$C:$C,'MCC Margin Analysis'!$A$1,'TB & MCC Cost Audit 2020-Curren'!$D:$D,'MCC Margin Analysis'!J$3,'TB & MCC Cost Audit 2020-Curren'!$A:$A,'MCC Margin Analysis'!$B4) -> 8509.5 | K4: =SUMIFS('TB & MCC Cost Audit 2020-Curren'!$W:$W,'TB & MCC Cost Audit 2020-Curren'!$C:$C,'MCC Margin Analysis'!$A$1,'TB & MCC Cost Audit 2020-Curren'!$D:$D,'MCC Margin Analysis'!K$3,'TB & MCC Cost Audit 2020-Curren'!$A:$A,'MCC Margin Analysis'!$B4) -> 4654.75 | L4: =SUMIFS('TB & MCC Cost Audit 2020-Curren'!$W:$W,'TB & MCC Cost Audit 2020-Curren'!$C:$C,'MCC Margin Analysis'!$A$1,'TB & MCC Cost Audit 2020-Curren'!$D:$D,'MCC Margin Analysis'!L$3,'TB & MCC Cost Audit 2020-Curren'!$A:$A,'MCC Margin Analysis'!$B4) -> 4572.81 | M4: =SUMIFS('TB & MCC Cost Audit 2020-Curren'!$W:$W,'TB & MCC Cost Audit 2020-Curren'!$C:$C,'MCC Margin Analysis'!$A$1,'TB & MCC Cost Audit 2020-Curren'!$D:$D,'MCC Margin Analysis'!M$3,'TB & MCC Cost Audit 2020-Curren'!$A:$A,'MCC Margin Analysis'!$B4) -> 4543.06 | N4: =SUMIFS('TB & MCC Cost Audit 2020-Curren'!$W:$W,'TB & MCC Cost Audit 2020-Curren'!$C:$C,'MCC Margin Analysis'!$A$1,'TB & MCC Cost Audit 2020-Curren'!$D:$D,'MCC Margin Analysis'!N$3,'TB & MCC Cost Audit 2020-Curren'!$A:$A,'MCC Margin Analysis'!$B4) -> 6316.41 | Q4: =IFERROR((C4-J4)/C4," - ") -> 0.79079801 | R4: =IFERROR((D4-K4)/D4," - ") -> 0.85138091 | S4: =IFERROR((E4-L4)/E4," - ") -> 0.85685814 | T4: =IFERROR((F4-M4)/F4," - ") -> 0.8605739 | U4: =IFERROR((G4-N4)/G4," - ") -> 0.80995276
B5: Albemarle | C5: =SUMIFS('TB & MCC Cost Audit 2020-Curren'!$P:$P,'TB & MCC Cost Audit 2020-Curren'!$C:$C,'MCC Margin Analysis'!$A$1,'TB & MCC Cost Audit 2020-Curren'!$D:$D,'MCC Margin Analysis'!C$3,'TB & MCC Cost Audit 2020-Curren'!$A:$A,'MCC Margin Analysis'!$B5) -> 0 | D5: =SUMIFS('TB & MCC Cost Audit 2020-Curren'!$P:$P,'TB & MCC Cost Audit 2020-Curren'!$C:$C,'MCC Margin Analysis'!$A$1,'TB & MCC Cost Audit 2020-Curren'!$D:$D,'MCC Margin Analysis'!D$3,'TB & MCC Cost Audit 2020-Curren'!$A:$A,'MCC Margin Analysis'!$B5) -> 0 | E5: =SUMIFS('TB & MCC Cost Audit 2020-Curren'!$P:$P,'TB & MCC Cost Audit 2020-Curren'!$C:$C,'MCC Margin Analysis'!$A$1,'TB & MCC Cost Audit 2020-Curren'!$D:$D,'MCC Margin Analysis'!E$3,'TB & MCC Cost Audit 2020-Curren'!$A:$A,'MCC Margin Analysis'!$B5) -> 0 | F5: =SUMIFS('TB & MCC Cost Audit 2020-Curren'!$P:$P,'TB & MCC Cost Audit 2020-Curren'!$C:$C,'MCC Margin Analysis'!$A$1,'TB & MCC Cost Audit 2020-Curren'!$D:$D,'MCC Margin Analysis'!F$3,'TB & MCC Cost Audit 2020-Curren'!$A:$A,'MCC Margin Analysis'!$B5) -> 0 | G5: =SUMIFS('TB & MCC Cost Audit 2020-Curren'!$P:$P,'TB & MCC Cost Audit 2020-Curren'!$C:$C,'MCC Margin Analysis'!$A$1,'TB & MCC Cost Audit 2020-Curren'!$D:$D,'MCC Margin Analysis'!G$3,'TB & MCC Cost Audit 2020-Curren'!$A:$A,'MCC Margin Analysis'!$B5) -> 0 | J5: =SUMIFS('TB & MCC Cost Audit 2020-Curren'!$W:$W,'TB & MCC Cost Audit 2020-Curren'!$C:$C,'MCC Margin Analysis'!$A$1,'TB & MCC Cost Audit 2020-Curren'!$D:$D,'MCC Margin Analysis'!J$3,'TB & MCC Cost Audit 2020-Curren'!$A:$A,'MCC Margin Analysis'!$B5) -> 0 | K5: =SUMIFS('TB & MCC Cost Audit 2020-Curren'!$W:$W,'TB & MCC Cost Audit 2020-Curren'!$C:$C,'MCC Margin Analysis'!$A$1,'TB & MCC Cost Audit 2020-Curren'!$D:$D,'MCC Margin Analysis'!K$3,'TB & MCC Cost Audit 2020-Curren'!$A:$A,'MCC Margin Analysis'!$B5) -> 0 | L5: =SUMIFS('TB & MCC Cost Audit 2020-Curren'!$W:$W,'TB & MCC Cost Audit 2020-Curren'!$C:$C,'MCC Margin Analysis'!$A$1,'TB & MCC Cost Audit 2020-Curren'!$D:$D,'MCC Margin Analysis'!L$3,'TB & MCC Cost Audit 2020-Curren'!$A:$A,'MCC Margin Analysis'!$B5) -> 0 | M5: =SUMIFS('TB & MCC Cost Audit 2020-Curren'!$W:$W,'TB & MCC Cost Audit 2020-Curren'!$C:$C,'MCC Margin Analysis'!$A$1,'TB & MCC Cost Audit 2020-Curren'!$D:$D,'MCC Margin Analysis'!M$3,'TB & MCC Cost Audit 2020-Curren'!$A:$A,'MCC Margin Analysis'!$B5) -> 0 | N5: =SUMIFS('TB & MCC Cost Audit 2020-Curren'!$W:$W,'TB & MCC Cost Audit 2020-Curren'!$C:$C,'MCC Margin Analysis'!$A$1,'TB & MCC Cost Audit 2020-Curren'!$D:$D,'MCC Margin Analysis'!N$3,'TB & MCC Cost Audit 2020-Curren'!$A:$A,'MCC Margin Analysis'!$B5) -> 0 | Q5: =IFERROR((C5-J5)/C5," - ") -> - | R5: =IFERROR((D5-K5)/D5," - ") -> - | S5: =IFERROR((E5-L5)/E5," - ") -> - | T5: =IFERROR((F5-M5)/F5," - ") -> - | U5: =IFERROR((G5-N5)/G5," - ") -> -
B6: Allen | C6: =SUMIFS('TB & MCC Cost Audit 2020-Curren'!$P:$P,'TB & MCC Cost Audit 2020-Curren'!$C:$C,'MCC Margin Analysis'!$A$1,'TB & MCC Cost Audit 2020-Curren'!$D:$D,'MCC Margin Analysis'!C$3,'TB & MCC Cost Audit 2020-Curren'!$A:$A,'MCC Margin Analysis'!$B6) -> 0 | D6: =SUMIFS('TB & MCC Cost Audit 2020-Curren'!$P:$P,'TB & MCC Cost Audit 2020-Curren'!$C:$C,'MCC Margin Analysis'!$A$1,'TB & MCC Cost Audit 2020-Curren'!$D:$D,'MCC Margin Analysis'!D$3,'TB & MCC Cost Audit 2020-Curren'!$A:$A,'MCC Margin Analysis'!$B6) -> 0 | E6: =SUMIFS('TB & MCC Cost Audit 2020-Curren'!$P:$P,'TB & MCC Cost Audit 2020-Curren'!$C:$C,'MCC Margin Analysis'!$A$1,'TB & MCC Cost Audit 2020-Curren'!$D:$D,'MCC Margin Analysis'!E$3,'TB & MCC Cost Audit 2020-Curren'!$A:$A,'MCC Margin Analysis'!$B6) -> 9680 | F6: =SUMIFS('TB & MCC Cost Audit 2020-Curren'!$P:$P,'TB & MCC Cost Audit 2020-Curren'!$C:$C,'MCC Margin Analysis'!$A$1,'TB & MCC Cost Audit 2020-Curren'!$D:$D,'MCC Margin Analysis'!F$3,'TB & MCC Cost Audit 2020-Curren'!$A:$A,'MCC Margin Analysis'!$B6) -> 9680 | G6: =SUMIFS('TB & MCC Cost Audit 2020-Curren'!$P:$P,'TB & MCC Cost Audit 2020-Curren'!$C:$C,'MCC Margin Analysis'!$A$1,'TB & MCC Cost Audit 2020-Curren'!$D:$D,'MCC Margin Analysis'!G$3,'TB & MCC Cost Audit 2020-Curren'!$A:$A,'MCC Margin Analysis'!$B6) -> 9680 | J6: =SUMIFS('TB & MCC Cost Audit 2020-Curren'!$W:$W,'TB & MCC Cost Audit 2020-Curren'!$C:$C,'MCC Margin Analysis'!$A$1,'TB & MCC Cost Audit 2020-Curren'!$D:$D,'MCC Margin Analysis'!J$3,'TB & MCC Cost Audit 2020-Curren'!$A:$A,'MCC Margin Analysis'!$B6) -> 0 | K6: =SUMIFS('TB & MCC Cost Audit 2020-Curren'!$W:$W,'TB & MCC Cost Audit 2020-Curren'!$C:$C,'MCC Margin Analysis'!$A$1,'TB & MCC Cost Audit 2020-Curren'!$D:$D,'MCC Margin Analysis'!K$3,'TB & MCC Cost Audit 2020-Curren'!$A:$A,'MCC Margin Analysis'!$B6) -> 0 | L6: =SUMIFS('TB & MCC Cost Audit 2020-Curren'!$W:$W,'TB & MCC Cost Audit 2020-Curren'!$C:$C,'MCC Margin Analysis'!$A$1,'TB & MCC Cost Audit 2020-Curren'!$D:$D,'MCC Margin Analysis'!L$3,'TB & MCC Cost Audit 2020-Curren'!$A:$A,'MCC Margin Analysis'!$B6) -> 3069 | M6: =SUMIFS('TB & MCC Cost Audit 2020-Curren'!$W:$W,'TB & MCC Cost Audit 2020-Curren'!$C:$C,'MCC Margin Analysis'!$A$1,'TB & MCC Cost Audit 2020-Curren'!$D:$D,'MCC Margin Analysis'!M$3,'TB & MCC Cost Audit 2020-Curren'!$A:$A,'MCC Margin Analysis'!$B6) -> 2866.47 | N6: =SUMIFS('TB & MCC Cost Audit 2020-Curren'!$W:$W,'TB & MCC Cost Audit 2020-Curren'!$C:$C,'MCC Margin Analysis'!$A$1,'TB & MCC Cost Audit 2020-Curren'!$D:$D,'MCC Margin Analysis'!N$3,'TB & MCC Cost Audit 2020-Curren'!$A:$A,'MCC Margin Analysis'!$B6) -> 4077.37 | Q6: =IFERROR((C6-J6)/C6," - ") -> - | R6: =IFERROR((D6-K6)/D6," - ") -> - | S6: =IFERROR((E6-L6)/E6," - ") -> 0.68295455 | T6: =IFERROR((F6-M6)/F6," - ") -> 0.70387707 | U6: =IFERROR((G6-N6)/G6," - ") -> 0.57878409
B7: Anne Arundel | C7: =SUMIFS('TB & MCC Cost Audit 2020-Curren'!$P:$P,'TB & MCC Cost Audit 2020-Curren'!$C:$C,'MCC Margin Analysis'!$A$1,'TB & MCC Cost Audit 2020-Curren'!$D:$D,'MCC Margin Analysis'!C$3,'TB & MCC Cost Audit 2020-Curren'!$A:$A,'MCC Margin Analysis'!$B7) -> 0 | D7: =SUMIFS('TB & MCC Cost Audit 2020-Curren'!$P:$P,'TB & MCC Cost Audit 2020-Curren'!$C:$C,'MCC Margin Analysis'!$A$1,'TB & MCC Cost Audit 2020-Curren'!$D:$D,'MCC Margin Analysis'!D$3,'TB & MCC Cost Audit 2020-Curren'!$A:$A,'MCC Margin Analysis'!$B7) -> 9353 | E7: =SUMIFS('TB & MCC Cost Audit 2020-Curren'!$P:$P,'TB & MCC Cost Audit 2020-Curren'!$C:$C,'MCC Margin Analysis'!$A$1,'TB & MCC Cost Audit 2020-Curren'!$D:$D,'MCC Margin Analysis'!E$3,'TB & MCC Cost Audit 2020-Curren'!$A:$A,'MCC Margin Analysis'!$B7) -> 9353 | F7: =SUMIFS('TB & MCC Cost Audit 2020-Curren'!$P:$P,'TB & MCC Cost Audit 2020-Curren'!$C:$C,'MCC Margin Analysis'!$A$1,'TB & MCC Cost Audit 2020-Curren'!$D:$D,'MCC Margin Analysis'!F$3,'TB & MCC Cost Audit 2020-Curren'!$A:$A,'MCC Margin Analysis'!$B7) -> 9353 | G7: =SUMIFS('TB & MCC Cost Audit 2020-Curren'!$P:$P,'TB & MCC Cost Audit 2020-Curren'!$C:$C,'MCC Margin Analysis'!$A$1,'TB & MCC Cost Audit 2020-Curren'!$D:$D,'MCC Margin Analysis'!G$3,'TB & MCC Cost Audit 2020-Curren'!$A:$A,'MCC Margin Analysis'!$B7) -> 9353 | J7: =SUMIFS('TB & MCC Cost Audit 2020-Curren'!$W:$W,'TB & MCC Cost Audit 2020-Curren'!$C:$C,'MCC Margin Analysis'!$A$1,'TB & MCC Cost Audit 2020-Curren'!$D:$D,'MCC Margin Analysis'!J$3,'TB & MCC Cost Audit 2020-Curren'!$A:$A,'MCC Margin Analysis'!$B7) -> 0 | K7: =SUMIFS('TB & MCC Cost Audit 2020-Curren'!$W:$W,'TB & MCC Cost Audit 2020-Curren'!$C:$C,'MCC Margin Analysis'!$A$1,'TB & MCC Cost Audit 2020-Curren'!$D:$D,'MCC Margin Analysis'!K$3,'TB & MCC Cost Audit 2020-Curren'!$A:$A,'MCC Margin Analysis'!$B7) -> 4420.05 | L7: =SUMIFS('TB & MCC Cost Audit 2020-Curren'!$W:$W,'TB & MCC Cost Audit 2020-Curren'!$C:$C,'MCC Margin Analysis'!$A$1,'TB & MCC Cost Audit 2020-Curren'!$D:$D,'MCC Margin Analysis'!L$3,'TB & MCC Cost Audit 2020-Curren'!$A:$A,'MCC Margin Analysis'!$B7) -> 3609.59 | M7: =SUMIFS('TB & MCC Cost Audit 2020-Curren'!$W:$W,'TB & MCC Cost Audit 2020-Curren'!$C:$C,'MCC Margin Analysis'!$A$1,'TB & MCC Cost Audit 2020-Curren'!$D:$D,'MCC Margin Analysis'!M$3,'TB & MCC Cost Audit 2020-Curren'!$A:$A,'MCC Margin Analysis'!$B7) -> 2346.39 | N7: =SUMIFS('TB & MCC Cost Audit 2020-Curren'!$W:$W,'TB & MCC Cost Audit 2020-Curren'!$C:$C,'MCC Margin Analysis'!$A$1,'TB & MCC Cost Audit 2020-Curren'!$D:$D,'MCC Margin Analysis'!N$3,'TB & MCC Cost Audit 2020-Curren'!$A:$A,'MCC Margin Analysis'!$B7) -> 4296.96 | Q7: =IFERROR((C7-J7)/C7," - ") -> - | R7: =IFERROR((D7-K7)/D7," - ") -> 0.52741901 | S7: =IFERROR((E7-L7)/E7," - ") -> 0.61407142 | T7: =IFERROR((F7-M7)/F7," - ") -> 0.74912969 | U7: =IFERROR((G7-N7)/G7," - ") -> 0.54057949
B8: Apex | C8: =SUMIFS('TB & MCC Cost Audit 2020-Curren'!$P:$P,'TB & MCC Cost Audit 2020-Curren'!$C:$C,'MCC Margin Analysis'!$A$1,'TB & MCC Cost Audit 2020-Curren'!$D:$D,'MCC Margin Analysis'!C$3,'TB & MCC Cost Audit 2020-Curren'!$A:$A,'MCC Margin Analysis'!$B8) -> 0 | D8: =SUMIFS('TB & MCC Cost Audit 2020-Curren'!$P:$P,'TB & MCC Cost Audit 2020-Curren'!$C:$C,'MCC Margin Analysis'!$A$1,'TB & MCC Cost Audit 2020-Curren'!$D:$D,'MCC Margin Analysis'!D$3,'TB & MCC Cost Audit 2020-Curren'!$A:$A,'MCC Margin Analysis'!$B8) -> 9116 | E8: =SUMIFS('TB & MCC Cost Audit 2020-Curren'!$P:$P,'TB & MCC Cost Audit 2020-Curren'!$C:$C,'MCC Margin Analysis'!$A$1,'TB & MCC Cost Audit 2020-Curren'!$D:$D,'MCC Margin Analysis'!E$3,'TB & MCC Cost Audit 2020-Curren'!$A:$A,'MCC Margin Analysis'!$B8) -> 12749 | F8: =SUMIFS('TB & MCC Cost Audit 2020-Curren'!$P:$P,'TB & MCC Cost Audit 2020-Curren'!$C:$C,'MCC Margin Analysis'!$A$1,'TB & MCC Cost Audit 2020-Curren'!$D:$D,'MCC Margin Analysis'!F$3,'TB & MCC Cost Audit 2020-Curren'!$A:$A,'MCC Margin Analysis'!$B8) -> 12084 | G8: =SUMIFS('TB & MCC Cost Audit 2020-Curren'!$P:$P,'TB & MCC Cost Audit 2020-Curren'!$C:$C,'MCC Margin Analysis'!$A$1,'TB & MCC Cost Audit 2020-Curren'!$D:$D,'MCC Margin Analysis'!G$3,'TB & MCC Cost Audit 2020-Curren'!$A:$A,'MCC Margin Analysis'!$B8) -> 11454 | J8: =SUMIFS('TB & MCC Cost Audit 2020-Curren'!$W:$W,'TB & MCC Cost Audit 2020-Curren'!$C:$C,'MCC Margin Analysis'!$A$1,'TB & MCC Cost Audit 2020-Curren'!$D:$D,'MCC Margin Analysis'!J$3,'TB & MCC Cost Audit 2020-Curren'!$A:$A,'MCC Margin Analysis'!$B8) -> 0 | K8: =SUMIFS('TB & MCC Cost Audit 2020-Curren'!$W:$W,'TB & MCC Cost Audit 2020-Curren'!$C:$C,'MCC Margin Analysis'!$A$1,'TB & MCC Cost Audit 2020-Curren'!$D:$D,'MCC Margin Analysis'!K$3,'TB & MCC Cost Audit 2020-Curren'!$A:$A,'MCC Margin Analysis'!$B8) -> 3394.42 | L8: =SUMIFS('TB & MCC Cost Audit 2020-Curren'!$W:$W,'TB & MCC Cost Audit 2020-Curren'!$C:$C,'MCC Margin Analysis'!$A$1,'TB & MCC Cost Audit 2020-Curren'!$D:$D,'MCC Margin Analysis'!L$3,'TB & MCC Cost Audit 2020-Curren'!$A:$A,'MCC Margin Analysis'!$B8) -> 3080.99 | M8: =SUMIFS('TB & MCC Cost Audit 2020-Curren'!$W:$W,'TB & MCC Cost Audit 2020-Curren'!$C:$C,'MCC Margin Analysis'!$A$1,'TB & MCC Cost Audit 2020-Curren'!$D:$D,'MCC Margin Analysis'!M$3,'TB & MCC Cost Audit 2020-Curren'!$A:$A,'MCC Margin Analysis'!$B8) -> 2341.53 | N8: =SUMIFS('TB & MCC Cost Audit 2020-Curren'!$W:$W,'TB & MCC Cost Audit 2020-Curren'!$C:$C,'MCC Margin Analysis'!$A$1,'TB & MCC Cost Audit 2020-Curren'!$D:$D,'MCC Margin Analysis'!N$3,'TB & MCC Cost Audit 2020-Curren'!$A:$A,'MCC Margin Analysis'!$B8) -> 1816.18 | Q8: =IFERROR((C8-J8)/C8," - ") -> - | R8: =IFERROR((D8-K8)/D8," - ") -> 0.62764151 | S8: =IFERROR((E8-L8)/E8," - ") -> 0.75833477 | T8: =IFERROR((F8-M8)/F8," - ") -> 0.8062289 | U8: =IFERROR((G8-N8)/G8," - ") -> 0.84143705
B9: Aqua Penn | C9: =SUMIFS('TB & MCC Cost Audit 2020-Curren'!$P:$P,'TB & MCC Cost Audit 2020-Curren'!$C:$C,'MCC Margin Analysis'!$A$1,'TB & MCC Cost Audit 2020-Curren'!$D:$D,'MCC Margin Analysis'!C$3,'TB & MCC Cost Audit 2020-Curren'!$A:$A,'MCC Margin Analysis'!$B9) -> 32434 | D9: =SUMIFS('TB & MCC Cost Audit 2020-Curren'!$P:$P,'TB & MCC Cost Audit 2020-Curren'!$C:$C,'MCC Margin Analysis'!$A$1,'TB & MCC Cost Audit 2020-Curren'!$D:$D,'MCC Margin Analysis'!D$3,'TB & MCC Cost Audit 2020-Curren'!$A:$A,'MCC Margin Analysis'!$B9) -> 0 | E9: =SUMIFS('TB & MCC Cost Audit 2020-Curren'!$P:$P,'TB & MCC Cost Audit 2020-Curren'!$C:$C,'MCC Margin Analysis'!$A$1,'TB & MCC Cost Audit 2020-Curren'!$D:$D,'MCC Margin Analysis'!E$3,'TB & MCC Cost Audit 2020-Curren'!$A:$A,'MCC Margin Analysis'!$B9) -> 41625 | F9: =SUMIFS('TB & MCC Cost Audit 2020-Curren'!$P:$P,'TB & MCC Cost Audit 2020-Curren'!$C:$C,'MCC Margin Analysis'!$A$1,'TB & MCC Cost Audit 2020-Curren'!$D:$D,'MCC Margin Analysis'!F$3,'TB & MCC Cost Audit 2020-Curren'!$A:$A,'MCC Margin Analysis'!$B9) -> 44749 | G9: =SUMIFS('TB & MCC Cost Audit 2020-Curren'!$P:$P,'TB & MCC Cost Audit 2020-Curren'!$C:$C,'MCC Margin Analysis'!$A$1,'TB & MCC Cost Audit 2020-Curren'!$D:$D,'MCC Margin Analysis'!G$3,'TB & MCC Cost Audit 2020-Curren'!$A:$A,'MCC Margin Analysis'!$B9) -> 48107 | J9: =SUMIFS('TB & MCC Cost Audit 2020-Curren'!$W:$W,'TB & MCC Cost Audit 2020-Curren'!$C:$C,'MCC Margin Analysis'!$A$1,'TB & MCC Cost Audit 2020-Curren'!$D:$D,'MCC Margin Analysis'!J$3,'TB & MCC Cost Audit 2020-Curren'!$A:$A,'MCC Margin Analysis'!$B9) -> 3232.83 | K9: =SUMIFS('TB & MCC Cost Audit 2020-Curren'!$W:$W,'TB & MCC Cost Audit 2020-Curren'!$C:$C,'MCC Margin Analysis'!$A$1,'TB & MCC Cost Audit 2020-Curren'!$D:$D,'MCC Margin Analysis'!K$3,'TB & MCC Cost Audit 2020-Curren'!$A:$A,'MCC Margin Analysis'!$B9) -> 0 | L9: =SUMIFS('TB & MCC Cost Audit 2020-Curren'!$W:$W,'TB & MCC Cost Audit 2020-Curren'!$C:$C,'MCC Margin Analysis'!$A$1,'TB & MCC Cost Audit 2020-Curren'!$D:$D,'MCC Margin Analysis'!L$3,'TB & MCC Cost Audit 2020-Curren'!$A:$A,'MCC Margin Analysis'!$B9) -> 5455.82 | M9: =SUMIFS('TB & MCC Cost Audit 2020-Curren'!$W:$W,'TB & MCC Cost Audit 2020-Curren'!$C:$C,'MCC Margin Analysis'!$A$1,'TB & MCC Cost Audit 2020-Curren'!$D:$D,'MCC Margin Analysis'!M$3,'TB & MCC Cost Audit 2020-Curren'!$A:$A,'MCC Margin Analysis'!$B9) -> 7193.03 | N9: =SUMIFS('TB & MCC Cost Audit 2020-Curren'!$W:$W,'TB & MCC Cost Audit 2020-Curren'!$C:$C,'MCC Margin Analysis'!$A$1,'TB & MCC Cost Audit 2020-Curren'!$D:$D,'MCC Margin Analysis'!N$3,'TB & MCC Cost Audit 2020-Curren'!$A:$A,'MCC Margin Analysis'!$B9) -> 11164.4 | Q9: =IFERROR((C9-J9)/C9," - ") -> 0.90032589 | R9: =IFERROR((D9-K9)/D9," - ") -> - | S9: =IFERROR((E9-L9)/E9," - ") -> 0.86892925 | T9: =IFERROR((F9-M9)/F9," - ") -> 0.83925831 | U9: =IFERROR((G9-N9)/G9," - ") -> 0.76792567
B10: Artesian Resources | C10: =SUMIFS('TB & MCC Cost Audit 2020-Curren'!$P:$P,'TB & MCC Cost Audit 2020-Curren'!$C:$C,'MCC Margin Analysis'!$A$1,'TB & MCC Cost Audit 2020-Curren'!$D:$D,'MCC Margin Analysis'!C$3,'TB & MCC Cost Audit 2020-Curren'!$A:$A,'MCC Margin Analysis'!$B10) -> 0 | D10: =SUMIFS('TB & MCC Cost Audit 2020-Curren'!$P:$P,'TB & MCC Cost Audit 2020-Curren'!$C:$C,'MCC Margin Analysis'!$A$1,'TB & MCC Cost Audit 2020-Curren'!$D:$D,'MCC Margin Analysis'!D$3,'TB & MCC Cost Audit 2020-Curren'!$A:$A,'MCC Margin Analysis'!$B10) -> 0 | E10: =SUMIFS('TB & MCC Cost Audit 2020-Curren'!$P:$P,'TB & MCC Cost Audit 2020-Curren'!$C:$C,'MCC Margin Analysis'!$A$1,'TB & MCC Cost Audit 2020-Curren'!$D:$D,'MCC Margin Analysis'!E$3,'TB & MCC Cost Audit 2020-Curren'!$A:$A,'MCC Margin Analysis'!$B10) -> 0 | F10: =SUMIFS('TB & MCC Cost Audit 2020-Curren'!$P:$P,'TB & MCC Cost Audit 2020-Curren'!$C:$C,'MCC Margin Analysis'!$A$1,'TB & MCC Cost Audit 2020-Curren'!$D:$D,'MCC Margin Analysis'!F$3,'TB & MCC Cost Audit 2020-Curren'!$A:$A,'MCC Margin Analysis'!$B10) -> 0 | G10: =SUMIFS('TB & MCC Cost Audit 2020-Curren'!$P:$P,'TB & MCC Cost Audit 2020-Curren'!$C:$C,'MCC Margin Analysis'!$A$1,'TB & MCC Cost Audit 2020-Curren'!$D:$D,'MCC Margin Analysis'!G$3,'TB & MCC Cost Audit 2020-Curren'!$A:$A,'MCC Margin Analysis'!$B10) -> 0 | J10: =SUMIFS('TB & MCC Cost Audit 2020-Curren'!$W:$W,'TB & MCC Cost Audit 2020-Curren'!$C:$C,'MCC Margin Analysis'!$A$1,'TB & MCC Cost Audit 2020-Curren'!$D:$D,'MCC Margin Analysis'!J$3,'TB & MCC Cost Audit 2020-Curren'!$A:$A,'MCC Margin Analysis'!$B10) -> 0 | K10: =SUMIFS('TB & MCC Cost Audit 2020-Curren'!$W:$W,'TB & MCC Cost Audit 2020-Curren'!$C:$C,'MCC Margin Analysis'!$A$1,'TB & MCC Cost Audit 2020-Curren'!$D:$D,'MCC Margin Analysis'!K$3,'TB & MCC Cost Audit 2020-Curren'!$A:$A,'MCC Margin Analysis'!$B10) -> 0 | L10: =SUMIFS('TB & MCC Cost Audit 2020-Curren'!$W:$W,'TB & MCC Cost Audit 2020-Curren'!$C:$C,'MCC Margin Analysis'!$A$1,'TB & MCC Cost Audit 2020-Curren'!$D:$D,'MCC Margin Analysis'!L$3,'TB & MCC Cost Audit 2020-Curren'!$A:$A,'MCC Margin Analysis'!$B10) -> 0 | M10: =SUMIFS('TB & MCC Cost Audit 2020-Curren'!$W:$W,'TB & MCC Cost Audit 2020-Curren'!$C:$C,'MCC Margin Analysis'!$A$1,'TB & MCC Cost Audit 2020-Curren'!$D:$D,'MCC Margin Analysis'!M$3,'TB & MCC Cost Audit 2020-Curren'!$A:$A,'MCC Margin Analysis'!$B10) -> 0 | N10: =SUMIFS('TB & MCC Cost Audit 2020-Curren'!$W:$W,'TB & MCC Cost Audit 2020-Curren'!$C:$C,'MCC Margin Analysis'!$A$1,'TB & MCC Cost Audit 2020-Curren'!$D:$D,'MCC Margin Analysis'!N$3,'TB & MCC Cost Audit 2020-Curren'!$A:$A,'MCC Margin Analysis'!$B10) -> 0 | Q10: =IFERROR((C10-J10)/C10," - ") -> - | R10: =IFERROR((D10-K10)/D10," - ") -> - | S10: =IFERROR((E10-L10)/E10," - ") -> - | T10: =IFERROR((F10-M10)/F10," - ") -> - | U10: =IFERROR((G10-N10)/G10," - ") -> -
B11: Aruba | C11: =SUMIFS('TB & MCC Cost Audit 2020-Curren'!$P:$P,'TB & MCC Cost Audit 2020-Curren'!$C:$C,'MCC Margin Analysis'!$A$1,'TB & MCC Cost Audit 2020-Curren'!$D:$D,'MCC Margin Analysis'!C$3,'TB & MCC Cost Audit 2020-Curren'!$A:$A,'MCC Margin Analysis'!$B11) -> 0 | D11: =SUMIFS('TB & MCC Cost Audit 2020-Curren'!$P:$P,'TB & MCC Cost Audit 2020-Curren'!$C:$C,'MCC Margin Analysis'!$A$1,'TB & MCC Cost Audit 2020-Curren'!$D:$D,'MCC Margin Analysis'!D$3,'TB & MCC Cost Audit 2020-Curren'!$A:$A,'MCC Margin Analysis'!$B11) -> 0 | E11: =SUMIFS('TB & MCC Cost Audit 2020-Curren'!$P:$P,'TB & MCC Cost Audit 2020-Curren'!$C:$C,'MCC Margin Analysis'!$A$1,'TB & MCC Cost Audit 2020-Curren'!$D:$D,'MCC Margin Analysis'!E$3,'TB & MCC Cost Audit 2020-Curren'!$A:$A,'MCC Margin Analysis'!$B11) -> 0 | F11: =SUMIFS('TB & MCC Cost Audit 2020-Curren'!$P:$P,'TB & MCC Cost Audit 2020-Curren'!$C:$C,'MCC Margin Analysis'!$A$1,'TB & MCC Cost Audit 2020-Curren'!$D:$D,'MCC Margin Analysis'!F$3,'TB & MCC Cost Audit 2020-Curren'!$A:$A,'MCC Margin Analysis'!$B11) -> 0 | G11: =SUMIFS('TB & MCC Cost Audit 2020-Curren'!$P:$P,'TB & MCC Cost Audit 2020-Curren'!$C:$C,'MCC Margin Analysis'!$A$1,'TB & MCC Cost Audit 2020-Curren'!$D:$D,'MCC Margin Analysis'!G$3,'TB & MCC Cost Audit 2020-Curren'!$A:$A,'MCC Margin Analysis'!$B11) -> 0 | J11: =SUMIFS('TB & MCC Cost Audit 2020-Curren'!$W:$W,'TB & MCC Cost Audit 2020-Curren'!$C:$C,'MCC Margin Analysis'!$A$1,'TB & MCC Cost Audit 2020-Curren'!$D:$D,'MCC Margin Analysis'!J$3,'TB & MCC Cost Audit 2020-Curren'!$A:$A,'MCC Margin Analysis'!$B11) -> 0 | K11: =SUMIFS('TB & MCC Cost Audit 2020-Curren'!$W:$W,'TB & MCC Cost Audit 2020-Curren'!$C:$C,'MCC Margin Analysis'!$A$1,'TB & MCC Cost Audit 2020-Curren'!$D:$D,'MCC Margin Analysis'!K$3,'TB & MCC Cost Audit 2020-Curren'!$A:$A,'MCC Margin Analysis'!$B11) -> 0 | L11: =SUMIFS('TB & MCC Cost Audit 2020-Curren'!$W:$W,'TB & MCC Cost Audit 2020-Curren'!$C:$C,'MCC Margin Analysis'!$A$1,'TB & MCC Cost Audit 2020-Curren'!$D:$D,'MCC Margin Analysis'!L$3,'TB & MCC Cost Audit 2020-Curren'!$A:$A,'MCC Margin Analysis'!$B11) -> 0 | M11: =SUMIFS('TB & MCC Cost Audit 2020-Curren'!$W:$W,'TB & MCC Cost Audit 2020-Curren'!$C:$C,'MCC Margin Analysis'!$A$1,'TB & MCC Cost Audit 2020-Curren'!$D:$D,'MCC Margin Analysis'!M$3,'TB & MCC Cost Audit 2020-Curren'!$A:$A,'MCC Margin Analysis'!$B11) -> 0 | N11: =SUMIFS('TB & MCC Cost Audit 2020-Curren'!$W:$W,'TB & MCC Cost Audit 2020-Curren'!$C:$C,'MCC Margin Analysis'!$A$1,'TB & MCC Cost Audit 2020-Curren'!$D:$D,'MCC Margin Analysis'!N$3,'TB & MCC Cost Audit 2020-Curren'!$A:$A,'MCC Margin Analysis'!$B11) -> 0 | Q11: =IFERROR((C11-J11)/C11," - ") -> - | R11: =IFERROR((D11-K11)/D11," - ") -> - | S11: =IFERROR((E11-L11)/E11," - ") -> - | T11: =IFERROR((F11-M11)/F11," - ") -> - | U11: =IFERROR((G11-N11)/G11," - ") -> -
B12: Austin | C12: =SUMIFS('TB & MCC Cost Audit 2020-Curren'!$P:$P,'TB & MCC Cost Audit 2020-Curren'!$C:$C,'MCC Margin Analysis'!$A$1,'TB & MCC Cost Audit 2020-Curren'!$D:$D,'MCC Margin Analysis'!C$3,'TB & MCC Cost Audit 2020-Curren'!$A:$A,'MCC Margin Analysis'!$B12) -> 17279 | D12: =SUMIFS('TB & MCC Cost Audit 2020-Curren'!$P:$P,'TB & MCC Cost Audit 2020-Curren'!$C:$C,'MCC Margin Analysis'!$A$1,'TB & MCC Cost Audit 2020-Curren'!$D:$D,'MCC Margin Analysis'!D$3,'TB & MCC Cost Audit 2020-Curren'!$A:$A,'MCC Margin Analysis'!$B12) -> 20445 | E12: =SUMIFS('TB & MCC Cost Audit 2020-Curren'!$P:$P,'TB & MCC Cost Audit 2020-Curren'!$C:$C,'MCC Margin Analysis'!$A$1,'TB & MCC Cost Audit 2020-Curren'!$D:$D,'MCC Margin Analysis'!E$3,'TB & MCC Cost Audit 2020-Curren'!$A:$A,'MCC Margin Analysis'!$B12) -> 19848 | F12: =SUMIFS('TB & MCC Cost Audit 2020-Curren'!$P:$P,'TB & MCC Cost Audit 2020-Curren'!$C:$C,'MCC Margin Analysis'!$A$1,'TB & MCC Cost Audit 2020-Curren'!$D:$D,'MCC Margin Analysis'!F$3,'TB & MCC Cost Audit 2020-Curren'!$A:$A,'MCC Margin Analysis'!$B12) -> 19269 | G12: =SUMIFS('TB & MCC Cost Audit 2020-Curren'!$P:$P,'TB & MCC Cost Audit 2020-Curren'!$C:$C,'MCC Margin Analysis'!$A$1,'TB & MCC Cost Audit 2020-Curren'!$D:$D,'MCC Margin Analysis'!G$3,'TB & MCC Cost Audit 2020-Curren'!$A:$A,'MCC Margin Analysis'!$B12) -> 18707 | J12: =SUMIFS('TB & MCC Cost Audit 2020-Curren'!$W:$W,'TB & MCC Cost Audit 2020-Curren'!$C:$C,'MCC Margin Analysis'!$A$1,'TB & MCC Cost Audit 2020-Curren'!$D:$D,'MCC Margin Analysis'!J$3,'TB & MCC Cost Audit 2020-Curren'!$A:$A,'MCC Margin Analysis'!$B12) -> 6455.24 | K12: =SUMIFS('TB & MCC Cost Audit 2020-Curren'!$W:$W,'TB & MCC Cost Audit 2020-Curren'!$C:$C,'MCC Margin Analysis'!$A$1,'TB & MCC Cost Audit 2020-Curren'!$D:$D,'MCC Margin Analysis'!K$3,'TB & MCC Cost Audit 2020-Curren'!$A:$A,'MCC Margin Analysis'!$B12) -> 4056.99 | L12: =SUMIFS('TB & MCC Cost Audit 2020-Curren'!$W:$W,'TB & MCC Cost Audit 2020-Curren'!$C:$C,'MCC Margin Analysis'!$A$1,'TB & MCC Cost Audit 2020-Curren'!$D:$D,'MCC Margin Analysis'!L$3,'TB & MCC Cost Audit 2020-Curren'!$A:$A,'MCC Margin Analysis'!$B12) -> 4362.94 | M12: =SUMIFS('TB & MCC Cost Audit 2020-Curren'!$W:$W,'TB & MCC Cost Audit 2020-Curren'!$C:$C,'MCC Margin Analysis'!$A$1,'TB & MCC Cost Audit 2020-Curren'!$D:$D,'MCC Margin Analysis'!M$3,'TB & MCC Cost Audit 2020-Curren'!$A:$A,'MCC Margin Analysis'!$B12) -> 4109.49 | N12: =SUMIFS('TB & MCC Cost Audit 2020-Curren'!$W:$W,'TB & MCC Cost Audit 2020-Curren'!$C:$C,'MCC Margin Analysis'!$A$1,'TB & MCC Cost Audit 2020-Curren'!$D:$D,'MCC Margin Analysis'!N$3,'TB & MCC Cost Audit 2020-Curren'!$A:$A,'MCC Margin Analysis'!$B12) -> 3760.63 | Q12: =IFERROR((C12-J12)/C12," - ") -> 0.62641125 | R12: =IFERROR((D12-K12)/D12," - ") -> 0.80156566 | S12: =IFERROR((E12-L12)/E12," - ") -> 0.78018239 | T12: =IFERROR((F12-M12)/F12," - ") -> 0.7867305 | U12: =IFERROR((G12-N12)/G12," - ") -> 0.79897204
B13: Badger | C13: =SUMIFS('TB & MCC Cost Audit 2020-Curren'!$P:$P,'TB & MCC Cost Audit 2020-Curren'!$C:$C,'MCC Margin Analysis'!$A$1,'TB & MCC Cost Audit 2020-Curren'!$D:$D,'MCC Margin Analysis'!C$3,'TB & MCC Cost Audit 2020-Curren'!$A:$A,'MCC Margin Analysis'!$B13) -> 0 | D13: =SUMIFS('TB & MCC Cost Audit 2020-Curren'!$P:$P,'TB & MCC Cost Audit 2020-Curren'!$C:$C,'MCC Margin Analysis'!$A$1,'TB & MCC Cost Audit 2020-Curren'!$D:$D,'MCC Margin Analysis'!D$3,'TB & MCC Cost Audit 2020-Curren'!$A:$A,'MCC Margin Analysis'!$B13) -> 0 | E13: =SUMIFS('TB & MCC Cost Audit 2020-Curren'!$P:$P,'TB & MCC Cost Audit 2020-Curren'!$C:$C,'MCC Margin Analysis'!$A$1,'TB & MCC Cost Audit 2020-Curren'!$D:$D,'MCC Margin Analysis'!E$3,'TB & MCC Cost Audit 2020-Curren'!$A:$A,'MCC Margin Analysis'!$B13) -> 0 | F13: =SUMIFS('TB & MCC Cost Audit 2020-Curren'!$P:$P,'TB & MCC Cost Audit 2020-Curren'!$C:$C,'MCC Margin Analysis'!$A$1,'TB & MCC Cost Audit 2020-Curren'!$D:$D,'MCC Margin Analysis'!F$3,'TB & MCC Cost Audit 2020-Curren'!$A:$A,'MCC Margin Analysis'!$B13) -> 0 | G13: =SUMIFS('TB & MCC Cost Audit 2020-Curren'!$P:$P,'TB & MCC Cost Audit 2020-Curren'!$C:$C,'MCC Margin Analysis'!$A$1,'TB & MCC Cost Audit 2020-Curren'!$D:$D,'MCC Margin Analysis'!G$3,'TB & MCC Cost Audit 2020-Curren'!$A:$A,'MCC Margin Analysis'!$B13) -> 0 | J13: =SUMIFS('TB & MCC Cost Audit 2020-Curren'!$W:$W,'TB & MCC Cost Audit 2020-Curren'!$C:$C,'MCC Margin Analysis'!$A$1,'TB & MCC Cost Audit 2020-Curren'!$D:$D,'MCC Margin Analysis'!J$3,'TB & MCC Cost Audit 2020-Curren'!$A:$A,'MCC Margin Analysis'!$B13) -> 0 | K13: =SUMIFS('TB & MCC Cost Audit 2020-Curren'!$W:$W,'TB & MCC Cost Audit 2020-Curren'!$C:$C,'MCC Margin Analysis'!$A$1,'TB & MCC Cost Audit 2020-Curren'!$D:$D,'MCC Margin Analysis'!K$3,'TB & MCC Cost Audit 2020-Curren'!$A:$A,'MCC Margin Analysis'!$B13) -> 0 | L13: =SUMIFS('TB & MCC Cost Audit 2020-Curren'!$W:$W,'TB & MCC Cost Audit 2020-Curren'!$C:$C,'MCC Margin Analysis'!$A$1,'TB & MCC Cost Audit 2020-Curren'!$D:$D,'MCC Margin Analysis'!L$3,'TB & MCC Cost Audit 2020-Curren'!$A:$A,'MCC Margin Analysis'!$B13) -> 0 | M13: =SUMIFS('TB & MCC Cost Audit 2020-Curren'!$W:$W,'TB & MCC Cost Audit 2020-Curren'!$C:$C,'MCC Margin Analysis'!$A$1,'TB & MCC Cost Audit 2020-Curren'!$D:$D,'MCC Margin Analysis'!M$3,'TB & MCC Cost Audit 2020-Curren'!$A:$A,'MCC Margin Analysis'!$B13) -> 0 | N13: =SUMIFS('TB & MCC Cost Audit 2020-Curren'!$W:$W,'TB & MCC Cost Audit 2020-Curren'!$C:$C,'MCC Margin Analysis'!$A$1,'TB & MCC Cost Audit 2020-Curren'!$D:$D,'MCC Margin Analysis'!N$3,'TB & MCC Cost Audit 2020-Curren'!$A:$A,'MCC Margin Analysis'!$B13) -> 0 | Q13: =IFERROR((C13-J13)/C13," - ") -> - | R13: =IFERROR((D13-K13)/D13," - ") -> - | S13: =IFERROR((E13-L13)/E13," - ") -> - | T13: =IFERROR((F13-M13)/F13," - ") -> - | U13: =IFERROR((G13-N13)/G13," - ") -> -
B14: Beverly Hills | C14: =SUMIFS('TB & MCC Cost Audit 2020-Curren'!$P:$P,'TB & MCC Cost Audit 2020-Curren'!$C:$C,'MCC Margin Analysis'!$A$1,'TB & MCC Cost Audit 2020-Curren'!$D:$D,'MCC Margin Analysis'!C$3,'TB & MCC Cost Audit 2020-Curren'!$A:$A,'MCC Margin Analysis'!$B14) -> 25403 | D14: =SUMIFS('TB & MCC Cost Audit 2020-Curren'!$P:$P,'TB & MCC Cost Audit 2020-Curren'!$C:$C,'MCC Margin Analysis'!$A$1,'TB & MCC Cost Audit 2020-Curren'!$D:$D,'MCC Margin Analysis'!D$3,'TB & MCC Cost Audit 2020-Curren'!$A:$A,'MCC Margin Analysis'!$B14) -> 14007 | E14: =SUMIFS('TB & MCC Cost Audit 2020-Curren'!$P:$P,'TB & MCC Cost Audit 2020-Curren'!$C:$C,'MCC Margin Analysis'!$A$1,'TB & MCC Cost Audit 2020-Curren'!$D:$D,'MCC Margin Analysis'!E$3,'TB & MCC Cost Audit 2020-Curren'!$A:$A,'MCC Margin Analysis'!$B14) -> 25403 | F14: =SUMIFS('TB & MCC Cost Audit 2020-Curren'!$P:$P,'TB & MCC Cost Audit 2020-Curren'!$C:$C,'MCC Margin Analysis'!$A$1,'TB & MCC Cost Audit 2020-Curren'!$D:$D,'MCC Margin Analysis'!F$3,'TB & MCC Cost Audit 2020-Curren'!$A:$A,'MCC Margin Analysis'!$B14) -> 25403 | G14: =SUMIFS('TB & MCC Cost Audit 2020-Curren'!$P:$P,'TB & MCC Cost Audit 2020-Curren'!$C:$C,'MCC Margin Analysis'!$A$1,'TB & MCC Cost Audit 2020-Curren'!$D:$D,'MCC Margin Analysis'!G$3,'TB & MCC Cost Audit 2020-Curren'!$A:$A,'MCC Margin Analysis'!$B14) -> 27437 | J14: =SUMIFS('TB & MCC Cost Audit 2020-Curren'!$W:$W,'TB & MCC Cost Audit 2020-Curren'!$C:$C,'MCC Margin Analysis'!$A$1,'TB & MCC Cost Audit 2020-Curren'!$D:$D,'MCC Margin Analysis'!J$3,'TB & MCC Cost Audit 2020-Curren'!$A:$A,'MCC Margin Analysis'!$B14) -> 6594.19 | K14: =SUMIFS('TB & MCC Cost Audit 2020-Curren'!$W:$W,'TB & MCC Cost Audit 2020-Curren'!$C:$C,'MCC Margin Analysis'!$A$1,'TB & MCC Cost Audit 2020-Curren'!$D:$D,'MCC Margin Analysis'!K$3,'TB & MCC Cost Audit 2020-Curren'!$A:$A,'MCC Margin Analysis'!$B14) -> 3321.06 | L14: =SUMIFS('TB & MCC Cost Audit 2020-Curren'!$W:$W,'TB & MCC Cost Audit 2020-Curren'!$C:$C,'MCC Margin Analysis'!$A$1,'TB & MCC Cost Audit 2020-Curren'!$D:$D,'MCC Margin Analysis'!L$3,'TB & MCC Cost Audit 2020-Curren'!$A:$A,'MCC Margin Analysis'!$B14) -> 3361.4 | M14: =SUMIFS('TB & MCC Cost Audit 2020-Curren'!$W:$W,'TB & MCC Cost Audit 2020-Curren'!$C:$C,'MCC Margin Analysis'!$A$1,'TB & MCC Cost Audit 2020-Curren'!$D:$D,'MCC Margin Analysis'!M$3,'TB & MCC Cost Audit 2020-Curren'!$A:$A,'MCC Margin Analysis'!$B14) -> 2951.93 | N14: =SUMIFS('TB & MCC Cost Audit 2020-Curren'!$W:$W,'TB & MCC Cost Audit 2020-Curren'!$C:$C,'MCC Margin Analysis'!$A$1,'TB & MCC Cost Audit 2020-Curren'!$D:$D,'MCC Margin Analysis'!N$3,'TB & MCC Cost Audit 2020-Curren'!$A:$A,'MCC Margin Analysis'!$B14) -> 4240.66 | Q14: =IFERROR((C14-J14)/C14," - ") -> 0.74041688 | R14: =IFERROR((D14-K14)/D14," - ") -> 0.76289998 | S14: =IFERROR((E14-L14)/E14," - ") -> 0.86767705 | T14: =IFERROR((F14-M14)/F14," - ") -> 0.88379601 | U14: =IFERROR((G14-N14)/G14," - ") -> 0.8454401
B15: Birmingham | C15: =SUMIFS('TB & MCC Cost Audit 2020-Curren'!$P:$P,'TB & MCC Cost Audit 2020-Curren'!$C:$C,'MCC Margin Analysis'!$A$1,'TB & MCC Cost Audit 2020-Curren'!$D:$D,'MCC Margin Analysis'!C$3,'TB & MCC Cost Audit 2020-Curren'!$A:$A,'MCC Margin Analysis'!$B15) -> 0 | D15: =SUMIFS('TB & MCC Cost Audit 2020-Curren'!$P:$P,'TB & MCC Cost Audit 2020-Curren'!$C:$C,'MCC Margin Analysis'!$A$1,'TB & MCC Cost Audit 2020-Curren'!$D:$D,'MCC Margin Analysis'!D$3,'TB & MCC Cost Audit 2020-Curren'!$A:$A,'MCC Margin Analysis'!$B15) -> 0 | E15: =SUMIFS('TB & MCC Cost Audit 2020-Curren'!$P:$P,'TB & MCC Cost Audit 2020-Curren'!$C:$C,'MCC Margin Analysis'!$A$1,'TB & MCC Cost Audit 2020-Curren'!$D:$D,'MCC Margin Analysis'!E$3,'TB & MCC Cost Audit 2020-Curren'!$A:$A,'MCC Margin Analysis'!$B15) -> 6188 | F15: =SUMIFS('TB & MCC Cost Audit 2020-Curren'!$P:$P,'TB & MCC Cost Audit 2020-Curren'!$C:$C,'MCC Margin Analysis'!$A$1,'TB & MCC Cost Audit 2020-Curren'!$D:$D,'MCC Margin Analysis'!F$3,'TB & MCC Cost Audit 2020-Curren'!$A:$A,'MCC Margin Analysis'!$B15) -> 0 | G15: =SUMIFS('TB & MCC Cost Audit 2020-Curren'!$P:$P,'TB & MCC Cost Audit 2020-Curren'!$C:$C,'MCC Margin Analysis'!$A$1,'TB & MCC Cost Audit 2020-Curren'!$D:$D,'MCC Margin Analysis'!G$3,'TB & MCC Cost Audit 2020-Curren'!$A:$A,'MCC Margin Analysis'!$B15) -> 0 | J15: =SUMIFS('TB & MCC Cost Audit 2020-Curren'!$W:$W,'TB & MCC Cost Audit 2020-Curren'!$C:$C,'MCC Margin Analysis'!$A$1,'TB & MCC Cost Audit 2020-Curren'!$D:$D,'MCC Margin Analysis'!J$3,'TB & MCC Cost Audit 2020-Curren'!$A:$A,'MCC Margin Analysis'!$B15) -> 0 | K15: =SUMIFS('TB & MCC Cost Audit 2020-Curren'!$W:$W,'TB & MCC Cost Audit 2020-Curren'!$C:$C,'MCC Margin Analysis'!$A$1,'TB & MCC Cost Audit 2020-Curren'!$D:$D,'MCC Margin Analysis'!K$3,'TB & MCC Cost Audit 2020-Curren'!$A:$A,'MCC Margin Analysis'!$B15) -> 0 | L15: =SUMIFS('TB & MCC Cost Audit 2020-Curren'!$W:$W,'TB & MCC Cost Audit 2020-Curren'!$C:$C,'MCC Margin Analysis'!$A$1,'TB & MCC Cost Audit 2020-Curren'!$D:$D,'MCC Margin Analysis'!L$3,'TB & MCC Cost Audit 2020-Curren'!$A:$A,'MCC Margin Analysis'!$B15) -> 830.28 | M15: =SUMIFS('TB & MCC Cost Audit 2020-Curren'!$W:$W,'TB & MCC Cost Audit 2020-Curren'!$C:$C,'MCC Margin Analysis'!$A$1,'TB & MCC Cost Audit 2020-Curren'!$D:$D,'MCC Margin Analysis'!M$3,'TB & MCC Cost Audit 2020-Curren'!$A:$A,'MCC Margin Analysis'!$B15) -> 0 | N15: =SUMIFS('TB & MCC Cost Audit 2020-Curren'!$W:$W,'TB & MCC Cost Audit 2020-Curren'!$C:$C,'MCC Margin Analysis'!$A$1,'TB & MCC Cost Audit 2020-Curren'!$D:$D,'MCC Margin Analysis'!N$3,'TB & MCC Cost Audit 2020-Curren'!$A:$A,'MCC Margin Analysis'!$B15) -> 0 | Q15: =IFERROR((C15-J15)/C15," - ") -> - | R15: =IFERROR((D15-K15)/D15," - ") -> - | S15: =IFERROR((E15-L15)/E15," - ") -> 0.86582418 | T15: =IFERROR((F15-M15)/F15," - ") -> - | U15: =IFERROR((G15-N15)/G15," - ") -> -
... B96: WSSC | C96: =SUMIFS('TB & MCC Cost Audit 2020-Curren'!$P:$P,'TB & MCC Cost Audit 2020-Curren'!$C:$C,'MCC Margin Analysis'!$A$1,'TB & MCC Cost Audit 2020-Curren'!$D:$D,'MCC Margin Analysis'!C$3,'TB & MCC Cost Audit 2020-Curren'!$A:$A,'MCC Margin Analysis'!$B96) -> 0 | D96: =SUMIFS('TB & MCC Cost Audit 2020-Curren'!$P:$P,'TB & MCC Cost Audit 2020-Curren'!$C:$C,'MCC Margin Analysis'!$A$1,'TB & MCC Cost Audit 2020-Curren'!$D:$D,'MCC Margin Analysis'!D$3,'TB & MCC Cost Audit 2020-Curren'!$A:$A,'MCC Margin Analysis'!$B96) -> 0 | E96: =SUMIFS('TB & MCC Cost Audit 2020-Curren'!$P:$P,'TB & MCC Cost Audit 2020-Curren'!$C:$C,'MCC Margin Analysis'!$A$1,'TB & MCC Cost Audit 2020-Curren'!$D:$D,'MCC Margin Analysis'!E$3,'TB & MCC Cost Audit 2020-Curren'!$A:$A,'MCC Margin Analysis'!$B96) -> 50646 | F96: =SUMIFS('TB & MCC Cost Audit 2020-Curren'!$P:$P,'TB & MCC Cost Audit 2020-Curren'!$C:$C,'MCC Margin Analysis'!$A$1,'TB & MCC Cost Audit 2020-Curren'!$D:$D,'MCC Margin Analysis'!F$3,'TB & MCC Cost Audit 2020-Curren'!$A:$A,'MCC Margin Analysis'!$B96) -> 53179 | G96: =SUMIFS('TB & MCC Cost Audit 2020-Curren'!$P:$P,'TB & MCC Cost Audit 2020-Curren'!$C:$C,'MCC Margin Analysis'!$A$1,'TB & MCC Cost Audit 2020-Curren'!$D:$D,'MCC Margin Analysis'!G$3,'TB & MCC Cost Audit 2020-Curren'!$A:$A,'MCC Margin Analysis'!$B96) -> 68641 | J96: =SUMIFS('TB & MCC Cost Audit 2020-Curren'!$W:$W,'TB & MCC Cost Audit 2020-Curren'!$C:$C,'MCC Margin Analysis'!$A$1,'TB & MCC Cost Audit 2020-Curren'!$D:$D,'MCC Margin Analysis'!J$3,'TB & MCC Cost Audit 2020-Curren'!$A:$A,'MCC Margin Analysis'!$B96) -> 0 | K96: =SUMIFS('TB & MCC Cost Audit 2020-Curren'!$W:$W,'TB & MCC Cost Audit 2020-Curren'!$C:$C,'MCC Margin Analysis'!$A$1,'TB & MCC Cost Audit 2020-Curren'!$D:$D,'MCC Margin Analysis'!K$3,'TB & MCC Cost Audit 2020-Curren'!$A:$A,'MCC Margin Analysis'!$B96) -> 0 | L96: =SUMIFS('TB & MCC Cost Audit 2020-Curren'!$W:$W,'TB & MCC Cost Audit 2020-Curren'!$C:$C,'MCC Margin Analysis'!$A$1,'TB & MCC Cost Audit 2020-Curren'!$D:$D,'MCC Margin Analysis'!L$3,'TB & MCC Cost Audit 2020-Curren'!$A:$A,'MCC Margin Analysis'!$B96) -> 8422.62 | M96: =SUMIFS('TB & MCC Cost Audit 2020-Curren'!$W:$W,'TB & MCC Cost Audit 2020-Curren'!$C:$C,'MCC Margin Analysis'!$A$1,'TB & MCC Cost Audit 2020-Curren'!$D:$D,'MCC Margin Analysis'!M$3,'TB & MCC Cost Audit 2020-Curren'!$A:$A,'MCC Margin Analysis'!$B96) -> 10801.52 | N96: =SUMIFS('TB & MCC Cost Audit 2020-Curren'!$W:$W,'TB & MCC Cost Audit 2020-Curren'!$C:$C,'MCC Margin Analysis'!$A$1,'TB & MCC Cost Audit 2020-Curren'!$D:$D,'MCC Margin Analysis'!N$3,'TB & MCC Cost Audit 2020-Curren'!$A:$A,'MCC Margin Analysis'!$B96) -> 7547.82 | Q96: =IFERROR((C96-J96)/C96," - ") -> - | R96: =IFERROR((D96-K96)/D96," - ") -> - | S96: =IFERROR((E96-L96)/E96," - ") -> 0.83369624 | T96: =IFERROR((F96-M96)/F96," - ") -> 0.79688373 | U96: =IFERROR((G96-N96)/G96," - ") -> 0.89003919

Sheet TB Type Margin Analysis
A1: TB
C2: =SUM(C4:C25) -> 3737600.8 | D2: =SUM(D4:D25) -> 4012052.8 | E2: =SUM(E4:E25) -> 3798485.8 | F2: =SUM(F4:F25) -> 5703742.2 | G2: =SUM(G4:G25) -> 4950309.3 | H2: =SUM(H4:H25) -> 7102651.4 | K2: =SUM(K4:K25) -> 1426781.2 | L2: =SUM(L4:L25) -> 1158465.4 | M2: =SUM(M4:M25) -> 944457.63 | N2: =SUM(N4:N25) -> 1496909.7 | O2: =SUM(O4:O25) -> 1179886.9 | P2: =SUM(P4:P25) -> 1437588 | S2: =IFERROR((C2-K2)/C2," - ") -> 0.61826282 | T2: =IFERROR((D2-L2)/D2," - ") -> 0.7112537 | U2: =IFERROR((E2-M2)/E2," - ") -> 0.75135944 | V2: =IFERROR((F2-N2)/F2," - ") -> 0.73755657 | W2: =IFERROR((G2-O2)/G2," - ") -> 0.7616539 | X2: =IFERROR((H2-P2)/H2," - ") -> 0.7975984
A3: Rev | B3: TB Type | C3: 2020 | D3: 2021 | E3: =D3+1 -> 2022 | F3: =E3+1 -> 2023 | G3: =F3+1 -> 2024 | H3: =G3+1 -> 2025 | J3: COGS | K3: 2020 | L3: 2021 | M3: =L3+1 -> 2022 | N3: =M3+1 -> 2023 | O3: =N3+1 -> 2024 | P3: =O3+1 -> 2025 | R3: GPM % | S3: 2020 | T3: 2021 | U3: =T3+1 -> 2022 | V3: =U3+1 -> 2023 | W3: =V3+1 -> 2024 | X3: =W3+1 -> 2025
B4: DISC | C4: =SUMIFS('TB & MCC Cost Audit 2020-Curren'!$P:$P,'TB & MCC Cost Audit 2020-Curren'!$C:$C,'TB Type Margin Analysis'!$B4,'TB & MCC Cost Audit 2020-Curren'!$D:$D,'TB Type Margin Analysis'!C$3) -> 0 | D4: =SUMIFS('TB & MCC Cost Audit 2020-Curren'!$P:$P,'TB & MCC Cost Audit 2020-Curren'!$C:$C,'TB Type Margin Analysis'!$B4,'TB & MCC Cost Audit 2020-Curren'!$D:$D,'TB Type Margin Analysis'!D$3) -> 0 | E4: =SUMIFS('TB & MCC Cost Audit 2020-Curren'!$P:$P,'TB & MCC Cost Audit 2020-Curren'!$C:$C,'TB Type Margin Analysis'!$B4,'TB & MCC Cost Audit 2020-Curren'!$D:$D,'TB Type Margin Analysis'!E$3) -> 0 | F4: =SUMIFS('TB & MCC Cost Audit 2020-Curren'!$P:$P,'TB & MCC Cost Audit 2020-Curren'!$C:$C,'TB Type Margin Analysis'!$B4,'TB & MCC Cost Audit 2020-Curren'!$D:$D,'TB Type Margin Analysis'!F$3) -> 0 | G4: =SUMIFS('TB & MCC Cost Audit 2020-Curren'!$P:$P,'TB & MCC Cost Audit 2020-Curren'!$C:$C,'TB Type Margin Analysis'!$B4,'TB & MCC Cost Audit 2020-Curren'!$D:$D,'TB Type Margin Analysis'!G$3) -> 0 | H4: =SUMIFS('TB & MCC Cost Audit 2020-Curren'!$P:$P,'TB & MCC Cost Audit 2020-Curren'!$C:$C,'TB Type Margin Analysis'!$B4,'TB & MCC Cost Audit 2020-Curren'!$D:$D,'TB Type Margin Analysis'!H$3) -> 0 | K4: =SUMIFS('TB & MCC Cost Audit 2020-Curren'!$W:$W,'TB & MCC Cost Audit 2020-Curren'!$C:$C,'TB Type Margin Analysis'!$B4,'TB & MCC Cost Audit 2020-Curren'!$D:$D,'TB Type Margin Analysis'!K$3) -> 0 | L4: =SUMIFS('TB & MCC Cost Audit 2020-Curren'!$W:$W,'TB & MCC Cost Audit 2020-Curren'!$C:$C,'TB Type Margin Analysis'!$B4,'TB & MCC Cost Audit 2020-Curren'!$D:$D,'TB Type Margin Analysis'!L$3) -> 0 | M4: =SUMIFS('TB & MCC Cost Audit 2020-Curren'!$W:$W,'TB & MCC Cost Audit 2020-Curren'!$C:$C,'TB Type Margin Analysis'!$B4,'TB & MCC Cost Audit 2020-Curren'!$D:$D,'TB Type Margin Analysis'!M$3) -> 0 | N4: =SUMIFS('TB & MCC Cost Audit 2020-Curren'!$W:$W,'TB & MCC Cost Audit 2020-Curren'!$C:$C,'TB Type Margin Analysis'!$B4,'TB & MCC Cost Audit 2020-Curren'!$D:$D,'TB Type Margin Analysis'!N$3) -> 0 | O4: =SUMIFS('TB & MCC Cost Audit 2020-Curren'!$W:$W,'TB & MCC Cost Audit 2020-Curren'!$C:$C,'TB Type Margin Analysis'!$B4,'TB & MCC Cost Audit 2020-Curren'!$D:$D,'TB Type Margin Analysis'!O$3) -> 0 | P4: =SUMIFS('TB & MCC Cost Audit 2020-Curren'!$W:$W,'TB & MCC Cost Audit 2020-Curren'!$C:$C,'TB Type Margin Analysis'!$B4,'TB & MCC Cost Audit 2020-Curren'!$D:$D,'TB Type Margin Analysis'!P$3) -> 0 | S4: =IFERROR((C4-K4)/C4," - ") -> - | T4: =IFERROR((D4-L4)/D4," - ") -> - | U4: =IFERROR((E4-M4)/E4," - ") -> - | V4: =IFERROR((F4-N4)/F4," - ") -> - | W4: =IFERROR((G4-O4)/G4," - ") -> - | X4: =IFERROR((H4-P4)/H4," - ") -> -
B5: DRM3 | C5: =SUMIFS('TB & MCC Cost Audit 2020-Curren'!$P:$P,'TB & MCC Cost Audit 2020-Curren'!$C:$C,'TB Type Margin Analysis'!$B5,'TB & MCC Cost Audit 2020-Curren'!$D:$D,'TB Type Margin Analysis'!C$3) -> 313901 | D5: =SUMIFS('TB & MCC Cost Audit 2020-Curren'!$P:$P,'TB & MCC Cost Audit 2020-Curren'!$C:$C,'TB Type Margin Analysis'!$B5,'TB & MCC Cost Audit 2020-Curren'!$D:$D,'TB Type Margin Analysis'!D$3) -> 451983.42 | E5: =SUMIFS('TB & MCC Cost Audit 2020-Curren'!$P:$P,'TB & MCC Cost Audit 2020-Curren'!$C:$C,'TB Type Margin Analysis'!$B5,'TB & MCC Cost Audit 2020-Curren'!$D:$D,'TB Type Margin Analysis'!E$3) -> 394747 | F5: =SUMIFS('TB & MCC Cost Audit 2020-Curren'!$P:$P,'TB & MCC Cost Audit 2020-Curren'!$C:$C,'TB Type Margin Analysis'!$B5,'TB & MCC Cost Audit 2020-Curren'!$D:$D,'TB Type Margin Analysis'!F$3) -> 552224 | G5: =SUMIFS('TB & MCC Cost Audit 2020-Curren'!$P:$P,'TB & MCC Cost Audit 2020-Curren'!$C:$C,'TB Type Margin Analysis'!$B5,'TB & MCC Cost Audit 2020-Curren'!$D:$D,'TB Type Margin Analysis'!G$3) -> 652359 | H5: =SUMIFS('TB & MCC Cost Audit 2020-Curren'!$P:$P,'TB & MCC Cost Audit 2020-Curren'!$C:$C,'TB Type Margin Analysis'!$B5,'TB & MCC Cost Audit 2020-Curren'!$D:$D,'TB Type Margin Analysis'!H$3) -> 977972 | K5: =SUMIFS('TB & MCC Cost Audit 2020-Curren'!$W:$W,'TB & MCC Cost Audit 2020-Curren'!$C:$C,'TB Type Margin Analysis'!$B5,'TB & MCC Cost Audit 2020-Curren'!$D:$D,'TB Type Margin Analysis'!K$3) -> 3901.15 | L5: =SUMIFS('TB & MCC Cost Audit 2020-Curren'!$W:$W,'TB & MCC Cost Audit 2020-Curren'!$C:$C,'TB Type Margin Analysis'!$B5,'TB & MCC Cost Audit 2020-Curren'!$D:$D,'TB Type Margin Analysis'!L$3) -> 16657.18 | M5: =SUMIFS('TB & MCC Cost Audit 2020-Curren'!$W:$W,'TB & MCC Cost Audit 2020-Curren'!$C:$C,'TB Type Margin Analysis'!$B5,'TB & MCC Cost Audit 2020-Curren'!$D:$D,'TB Type Margin Analysis'!M$3) -> 26161.57 | N5: =SUMIFS('TB & MCC Cost Audit 2020-Curren'!$W:$W,'TB & MCC Cost Audit 2020-Curren'!$C:$C,'TB Type Margin Analysis'!$B5,'TB & MCC Cost Audit 2020-Curren'!$D:$D,'TB Type Margin Analysis'!N$3) -> 21279.75 | O5: =SUMIFS('TB & MCC Cost Audit 2020-Curren'!$W:$W,'TB & MCC Cost Audit 2020-Curren'!$C:$C,'TB Type Margin Analysis'!$B5,'TB & MCC Cost Audit 2020-Curren'!$D:$D,'TB Type Margin Analysis'!O$3) -> 32999.21 | P5: =SUMIFS('TB & MCC Cost Audit 2020-Curren'!$W:$W,'TB & MCC Cost Audit 2020-Curren'!$C:$C,'TB Type Margin Analysis'!$B5,'TB & MCC Cost Audit 2020-Curren'!$D:$D,'TB Type Margin Analysis'!P$3) -> 42412.24 | S5: =IFERROR((C5-K5)/C5," - ") -> 0.98757204 | T5: =IFERROR((D5-L5)/D5," - ") -> 0.96314648 | U5: =IFERROR((E5-M5)/E5," - ") -> 0.93372573 | V5: =IFERROR((F5-N5)/F5," - ") -> 0.96146537 | W5: =IFERROR((G5-O5)/G5," - ") -> 0.94941557 | X5: =IFERROR((H5-P5)/H5," - ") -> 0.95663246
